<mujocoinclude>
    <body name="link_base" pos = "0.469 0.5 0" euler="0 0 3.1416" childclass="lite6">
      <!--
      0.469 0.5 0
      -0.00829545 3.26357e-05 0.0631195
      -->
      <inertial pos="-0.00829545 3.26357e-05 0.0631195" mass="1.65394" diaginertia="0 0 0"/>
      <geom class="visual" mesh="link_base"/>
      <geom class="collision" mesh="link_base_c"/>
      <body name="link1" pos="0 0 0.2435">
        <inertial pos="-0.00036 0.04195 -0.0025" quat="0.608059 0.792349 -0.0438707 0.0228718" mass="1.411"
          diaginertia="0.00145276 0.00135275 0.000853355"/>
        <joint name="joint1" range="-6.28319 6.28319"/>
        <geom class="visual" mesh="link1"/>
        <geom class="collision" mesh="link1_c"/>
        <body name="link2" quat="-1 1 1 1">
          <inertial pos="0.179 0 0.0584" quat="0.417561 0.571619 0.569585 0.417693" mass="1.34"
            diaginertia="0.00560971 0.0052152 0.00122018"/>
          <joint name="joint2" range="-2.61799 2.61799"/>
          <geom class="visual" mesh="link2"/>
          <geom class="collision" mesh="link2_c"/>
          <body name="link3" pos="0.2002 0 0" quat="-2.59734e-06 -0.707105 -0.707108 -2.59735e-06">
            <inertial pos="0.072 -0.0357 -0.001" quat="0.128259 0.662963 -0.167256 0.71837" mass="0.953"
              diaginertia="0.0018521 0.00175546 0.000703807"/>
            <joint name="joint3" range="-0.061087 5.23599"/>
            <geom class="visual" mesh="link3"/>
            <geom class="collision" mesh="link3_c"/>
            <body name="link4" pos="0.087 -0.22761 0" quat="0.707105 0.707108 0 0">
              <inertial pos="-0.002 -0.0285 -0.0813" quat="0.975248 0.22109 0.00203498 -0.00262178" mass="1.284"
                diaginertia="0.00370503 0.00349091 0.00109586"/>
              <joint name="joint4" range="-6.28319 6.28319"/>
              <geom class="visual" mesh="link4"/>
              <geom class="collision" mesh="link4_c"/>
              <body name="link5" quat="1 1 0 0">
                <inertial pos="0 0.01 0.0019" quat="0.71423 0.696388 -0.0531933 0.0456997" mass="0.804"
                  diaginertia="0.000567553 0.000529266 0.000507681"/>
                <joint name="joint5" range="-2.1642 2.1642"/>
                <geom class="visual" mesh="link5"/>
                <geom class="collision" mesh="link5_c"/>
                <body name="link6" pos="0 0.0625 0" quat="1 -1 0 0">
                  <inertial pos="0 -0.00194 -0.0102" quat="-0.0376023 0.704057 0.0446838 0.707738" mass="0.13"
                    diaginertia="0.000148148 8.57757e-05 7.71412e-05"/>
                  <joint name="joint6" range="-6.28319 6.28319"/>
                  <geom class="visual" mesh="link6" material="silver"/>
                  <geom class="collision" mesh="link6_c"/>
                  <site name="attachment_site"/>
                </body>
              </body>
            </body>
          </body>
        </body>
      </body>
    </body>
</mujocoinclude>